2020-01-13 13:43:38 [scrapy.utils.log] INFO: Scrapy 1.8.0 started (bot: scrapybot)
2020-01-13 13:43:38 [scrapy.utils.log] INFO: Versions: lxml 4.4.2.0, libxml2 2.9.10, cssselect 1.1.0, parsel 1.5.2, w3lib 1.21.0, Twisted 19.10.0, Python 3.6.8 (v3.6.8:3c6b436a57, Dec 24 2018, 02:10:22) - [GCC 4.2.1 (Apple Inc. build 5666) (dot 3)], pyOpenSSL 19.1.0 (OpenSSL 1.1.1d  10 Sep 2019), cryptography 2.8, Platform Darwin-19.0.0-x86_64-i386-64bit
2020-01-13 13:43:38 [scrapy.crawler] INFO: Overridden settings: {'LOG_FILE': 'logs/default/scraper/9905832635dc11eaa1731c36bbecd5bf.log', 'SPIDER_MODULES': ['scraper_app.spiders']}
2020-01-13 13:43:38 [scrapy.extensions.telnet] INFO: Telnet Password: fb4bb05c61ce70b7
2020-01-13 13:43:38 [scrapy.middleware] INFO: Enabled extensions:
['scrapy.extensions.corestats.CoreStats',
 'scrapy.extensions.telnet.TelnetConsole',
 'scrapy.extensions.memusage.MemoryUsage',
 'scrapy.extensions.logstats.LogStats']
2020-01-13 13:43:38 [scrapy.middleware] INFO: Enabled downloader middlewares:
['scrapy.downloadermiddlewares.httpauth.HttpAuthMiddleware',
 'scrapy.downloadermiddlewares.downloadtimeout.DownloadTimeoutMiddleware',
 'scrapy.downloadermiddlewares.defaultheaders.DefaultHeadersMiddleware',
 'scrapy.downloadermiddlewares.useragent.UserAgentMiddleware',
 'scrapy.downloadermiddlewares.retry.RetryMiddleware',
 'scrapy.downloadermiddlewares.redirect.MetaRefreshMiddleware',
 'scrapy.downloadermiddlewares.httpcompression.HttpCompressionMiddleware',
 'scrapy.downloadermiddlewares.redirect.RedirectMiddleware',
 'scrapy.downloadermiddlewares.cookies.CookiesMiddleware',
 'scrapy.downloadermiddlewares.httpproxy.HttpProxyMiddleware',
 'scrapy.downloadermiddlewares.stats.DownloaderStats']
2020-01-13 13:43:38 [scrapy.middleware] INFO: Enabled spider middlewares:
['scrapy.spidermiddlewares.httperror.HttpErrorMiddleware',
 'scrapy.spidermiddlewares.offsite.OffsiteMiddleware',
 'scrapy.spidermiddlewares.referer.RefererMiddleware',
 'scrapy.spidermiddlewares.urllength.UrlLengthMiddleware',
 'scrapy.spidermiddlewares.depth.DepthMiddleware']
2020-01-13 13:43:38 [scrapy.middleware] INFO: Enabled item pipelines:
['scraper_app.pipeline.StackPipeline']
2020-01-13 13:43:38 [scrapy.core.engine] INFO: Spider opened
2020-01-13 13:43:38 [scrapy.extensions.logstats] INFO: Crawled 0 pages (at 0 pages/min), scraped 0 items (at 0 items/min)
2020-01-13 13:43:38 [scrapy.extensions.telnet] INFO: Telnet console listening on 127.0.0.1:6023
2020-01-13 13:43:38 [scrapy.core.engine] DEBUG: Crawled (200) <GET http://127.0.0.1:3000/> (referer: None)
2020-01-13 13:43:38 [scrapy.core.scraper] DEBUG: Scraped from <200 http://127.0.0.1:3000/>
{'user_id': 29, 'user_name': 'Punyam', 'roll_no': '16ucs140'}
2020-01-13 13:43:38 [scrapy.core.scraper] DEBUG: Scraped from <200 http://127.0.0.1:3000/>
{'user_id': 4, 'user_name': 'Parth', 'roll_no': '16ucs143'}
2020-01-13 13:43:38 [scrapy.core.scraper] DEBUG: Scraped from <200 http://127.0.0.1:3000/>
{'user_id': 40, 'user_name': 'Vaibhav', 'roll_no': '16ucs147'}
2020-01-13 13:43:38 [scrapy.core.scraper] DEBUG: Scraped from <200 http://127.0.0.1:3000/>
{'user_id': 20, 'user_name': 'prince', 'roll_no': '16ucs142'}
2020-01-13 13:43:38 [scrapy.core.scraper] DEBUG: Scraped from <200 http://127.0.0.1:3000/>
{'user_id': 2, 'user_name': 'dgfhdgh', 'roll_no': '16ucs141'}
2020-01-13 13:43:38 [scrapy.core.scraper] DEBUG: Scraped from <200 http://127.0.0.1:3000/>
{'user_id': 5, 'user_name': 'new_one', 'roll_no': '16ucs152'}
2020-01-13 13:43:38 [scrapy.core.scraper] DEBUG: Scraped from <200 http://127.0.0.1:3000/>
{'user_id': 6, 'user_name': 'west', 'roll_no': '16ucs122'}
2020-01-13 13:43:38 [scrapy.core.scraper] DEBUG: Scraped from <200 http://127.0.0.1:3000/>
{'user_id': 8, 'user_name': 'dgfhdgh', 'roll_no': '16ucs158'}
2020-01-13 13:43:38 [scrapy.core.scraper] ERROR: Error processing {'user_id': 4, 'user_name': 'John', 'roll_no': '16ucs021'}
Traceback (most recent call last):
  File "/Users/admin/Desktop/Development/yourenv/lib/python3.6/site-packages/sqlalchemy/engine/base.py", line 1246, in _execute_context
    cursor, statement, parameters, context
  File "/Users/admin/Desktop/Development/yourenv/lib/python3.6/site-packages/sqlalchemy/engine/default.py", line 581, in do_execute
    cursor.execute(statement, parameters)
psycopg2.errors.UniqueViolation: duplicate key value violates unique constraint "scrappy_pkey"
DETAIL:  Key (user_id)=(4) already exists.


The above exception was the direct cause of the following exception:

Traceback (most recent call last):
  File "/Users/admin/Desktop/Development/yourenv/lib/python3.6/site-packages/twisted/internet/defer.py", line 654, in _runCallbacks
    current.result = callback(current.result, *args, **kw)
  File "/Users/admin/Desktop/Development/scraper_app/pipeline.py", line 22, in process_item
    session.commit()
  File "/Users/admin/Desktop/Development/yourenv/lib/python3.6/site-packages/sqlalchemy/orm/session.py", line 1036, in commit
    self.transaction.commit()
  File "/Users/admin/Desktop/Development/yourenv/lib/python3.6/site-packages/sqlalchemy/orm/session.py", line 503, in commit
    self._prepare_impl()
  File "/Users/admin/Desktop/Development/yourenv/lib/python3.6/site-packages/sqlalchemy/orm/session.py", line 482, in _prepare_impl
    self.session.flush()
  File "/Users/admin/Desktop/Development/yourenv/lib/python3.6/site-packages/sqlalchemy/orm/session.py", line 2479, in flush
    self._flush(objects)
  File "/Users/admin/Desktop/Development/yourenv/lib/python3.6/site-packages/sqlalchemy/orm/session.py", line 2617, in _flush
    transaction.rollback(_capture_exception=True)
  File "/Users/admin/Desktop/Development/yourenv/lib/python3.6/site-packages/sqlalchemy/util/langhelpers.py", line 68, in __exit__
    compat.reraise(exc_type, exc_value, exc_tb)
  File "/Users/admin/Desktop/Development/yourenv/lib/python3.6/site-packages/sqlalchemy/util/compat.py", line 153, in reraise
    raise value
  File "/Users/admin/Desktop/Development/yourenv/lib/python3.6/site-packages/sqlalchemy/orm/session.py", line 2577, in _flush
    flush_context.execute()
  File "/Users/admin/Desktop/Development/yourenv/lib/python3.6/site-packages/sqlalchemy/orm/unitofwork.py", line 422, in execute
    rec.execute(self)
  File "/Users/admin/Desktop/Development/yourenv/lib/python3.6/site-packages/sqlalchemy/orm/unitofwork.py", line 589, in execute
    uow,
  File "/Users/admin/Desktop/Development/yourenv/lib/python3.6/site-packages/sqlalchemy/orm/persistence.py", line 245, in save_obj
    insert,
  File "/Users/admin/Desktop/Development/yourenv/lib/python3.6/site-packages/sqlalchemy/orm/persistence.py", line 1084, in _emit_insert_statements
    c = cached_connections[connection].execute(statement, multiparams)
  File "/Users/admin/Desktop/Development/yourenv/lib/python3.6/site-packages/sqlalchemy/engine/base.py", line 982, in execute
    return meth(self, multiparams, params)
  File "/Users/admin/Desktop/Development/yourenv/lib/python3.6/site-packages/sqlalchemy/sql/elements.py", line 287, in _execute_on_connection
    return connection._execute_clauseelement(self, multiparams, params)
  File "/Users/admin/Desktop/Development/yourenv/lib/python3.6/site-packages/sqlalchemy/engine/base.py", line 1101, in _execute_clauseelement
    distilled_params,
  File "/Users/admin/Desktop/Development/yourenv/lib/python3.6/site-packages/sqlalchemy/engine/base.py", line 1250, in _execute_context
    e, statement, parameters, cursor, context
  File "/Users/admin/Desktop/Development/yourenv/lib/python3.6/site-packages/sqlalchemy/engine/base.py", line 1476, in _handle_dbapi_exception
    util.raise_from_cause(sqlalchemy_exception, exc_info)
  File "/Users/admin/Desktop/Development/yourenv/lib/python3.6/site-packages/sqlalchemy/util/compat.py", line 398, in raise_from_cause
    reraise(type(exception), exception, tb=exc_tb, cause=cause)
  File "/Users/admin/Desktop/Development/yourenv/lib/python3.6/site-packages/sqlalchemy/util/compat.py", line 152, in reraise
    raise value.with_traceback(tb)
  File "/Users/admin/Desktop/Development/yourenv/lib/python3.6/site-packages/sqlalchemy/engine/base.py", line 1246, in _execute_context
    cursor, statement, parameters, context
  File "/Users/admin/Desktop/Development/yourenv/lib/python3.6/site-packages/sqlalchemy/engine/default.py", line 581, in do_execute
    cursor.execute(statement, parameters)
sqlalchemy.exc.IntegrityError: (psycopg2.errors.UniqueViolation) duplicate key value violates unique constraint "scrappy_pkey"
DETAIL:  Key (user_id)=(4) already exists.

[SQL: INSERT INTO scrappy (user_id, user_name, roll_no) VALUES (%(user_id)s, %(user_name)s, %(roll_no)s)]
[parameters: {'user_id': 4, 'user_name': 'John', 'roll_no': '16ucs021'}]
(Background on this error at: http://sqlalche.me/e/gkpj)
2020-01-13 13:43:38 [scrapy.core.scraper] DEBUG: Scraped from <200 http://127.0.0.1:3000/>
{'user_id': 80, 'user_name': 'sql_query', 'roll_no': '16ucs159'}
2020-01-13 13:43:38 [scrapy.core.scraper] ERROR: Spider error processing <GET http://127.0.0.1:3000/> (referer: None)
Traceback (most recent call last):
  File "/Users/admin/Desktop/Development/yourenv/lib/python3.6/site-packages/scrapy/utils/defer.py", line 102, in iter_errback
    yield next(it)
  File "/Users/admin/Desktop/Development/yourenv/lib/python3.6/site-packages/scrapy/core/spidermw.py", line 84, in evaluate_iterable
    for r in iterable:
  File "/Users/admin/Desktop/Development/yourenv/lib/python3.6/site-packages/scrapy/spidermiddlewares/offsite.py", line 29, in process_spider_output
    for x in result:
  File "/Users/admin/Desktop/Development/yourenv/lib/python3.6/site-packages/scrapy/core/spidermw.py", line 84, in evaluate_iterable
    for r in iterable:
  File "/Users/admin/Desktop/Development/yourenv/lib/python3.6/site-packages/scrapy/spidermiddlewares/referer.py", line 339, in <genexpr>
    return (_set_referer(r) for r in result or ())
  File "/Users/admin/Desktop/Development/yourenv/lib/python3.6/site-packages/scrapy/core/spidermw.py", line 84, in evaluate_iterable
    for r in iterable:
  File "/Users/admin/Desktop/Development/yourenv/lib/python3.6/site-packages/scrapy/spidermiddlewares/urllength.py", line 37, in <genexpr>
    return (r for r in result or () if _filter(r))
  File "/Users/admin/Desktop/Development/yourenv/lib/python3.6/site-packages/scrapy/core/spidermw.py", line 84, in evaluate_iterable
    for r in iterable:
  File "/Users/admin/Desktop/Development/yourenv/lib/python3.6/site-packages/scrapy/spidermiddlewares/depth.py", line 58, in <genexpr>
    return (r for r in result or () if _filter(r))
  File "/Users/admin/Desktop/Development/scraper_app/spiders/spider.py", line 28, in parse
    items = {'user_id': arr[i], 'user_name': arr[i + 1], 'roll_no': arr[i + 2]}
IndexError: list index out of range
2020-01-13 13:43:38 [scrapy.core.engine] INFO: Closing spider (finished)
2020-01-13 13:43:38 [scrapy.statscollectors] INFO: Dumping Scrapy stats:
{'downloader/request_bytes': 208,
 'downloader/request_count': 1,
 'downloader/request_method_count/GET': 1,
 'downloader/response_bytes': 354,
 'downloader/response_count': 1,
 'downloader/response_status_count/200': 1,
 'elapsed_time_seconds': 0.207952,
 'finish_reason': 'finished',
 'finish_time': datetime.datetime(2020, 1, 13, 8, 13, 38, 892409),
 'item_scraped_count': 9,
 'log_count/DEBUG': 10,
 'log_count/ERROR': 2,
 'log_count/INFO': 10,
 'memusage/max': 75894784,
 'memusage/startup': 75894784,
 'response_received_count': 1,
 'scheduler/dequeued': 1,
 'scheduler/dequeued/memory': 1,
 'scheduler/enqueued': 1,
 'scheduler/enqueued/memory': 1,
 'spider_exceptions/IndexError': 1,
 'start_time': datetime.datetime(2020, 1, 13, 8, 13, 38, 684457)}
2020-01-13 13:43:38 [scrapy.core.engine] INFO: Spider closed (finished)
